Workbook

Sheet 说明 Instructions
A1: Gold SQL 独立复核表 / Independent Review of the Gold-Standard SQL
A2: 研究：Comparing LLMs and Prompt Engineering Methods for NL2SQL in Academic Library Scenarios（何修成 Xiucheng He, Stamford International University）
A4: 请您做什么 / What to do
A5: 1. 在「复核 Review」表中逐条阅读【问题】与【Gold SQL】，并参考【执行结果】判断该 SQL 是否正确回答了问题。
A6: 2. 在黄色格子里填写：【判定】从下拉框选（正确 / 有误 / 问题有歧义）；若选“有误”或“有歧义”，请在【说明】中写明原因，并尽量在【建议的 SQL】中给出您认为正确的写法。
A7: 3. 只需判断 SQL 与问题是否一致，不需要评价问题出得好不好；同一问题有多种等价写法时，只要结果正确即算“正确”。
A8: 4. 数据库结构、术语约定见「数据库结构 Schema」表；日期为 'YYYY-MM-DD' 文本，未归还时 return_date 为 NULL。
A9: 5. 全部填完后，请在「复核人信息 Reviewer」表填写您的姓名、职称、单位和完成日期。论文中将写明复核人的身份与复核结果。
A11: 判定标准 / Judgement options
A12: 正确 Correct：SQL 的结果准确回答了问题。
A13: 有误 Incorrect：SQL 漏条件、多条件、连错表、聚合或排序错误等，结果不能回答问题。
A14: 问题有歧义 Ambiguous：问题本身可以有两种以上合理理解，而 SQL 只对应其中一种（请写明另一种理解）。
... A19: 预计用时：约 3–4 小时。共 200 条：L1 简单 50、L2 聚合 50、L3 多表连接 50、L4 嵌套 50。

Sheet 复核 Review
A1: 编号 ID | B1: 难度 Level | C1: 问题 Question | D1: Gold SQL | E1: 结果行数 Rows | F1: 执行结果（前5行）Result preview | G1: 判定 Judgement | H1: 说明 Reason | I1: 建议的 SQL Suggested SQL | J1: 备注 Notes
A2: L1-001 | B2: L1 简单 Simple | C2: 查找2025年出版的所有图书的书名和作者 | D2: SELECT title, author FROM books WHERE publish_year = 2025 | E2: 12 | F2: title | author 人工智能：现代方法 | Russell SQL必知必会 | Forta 深度学习入门 | 斋藤康毅 Python编程实践 | Matthes 呐喊 | 马伟 … | G2: 正确
A3: L1-002 | B3: L1 简单 Simple | C3: 查询所有教师读者的姓名和学院 | D3: SELECT name, department FROM readers WHERE reader_type = '教师' | E3: 10 | F3: name | department 赵敏 | 文学院 林雪 | 管理学院 罗欣怡 | 管理学院 马磊然 | 管理学院 赵若曦 | 经济学院 … | G3: 正确
A4: L1-003 | B4: L1 简单 Simple | C4: 列出馆藏复本总数超过15册的图书书名 | D4: SELECT title FROM books WHERE total_copies > 15 | E4: 49 | F4: title 活着 算法导论 呐喊 白鹿原 了不起的盖茨比 … | G4: 正确
A5: L1-004 | B5: L1 简单 Simple | C5: 帮我拉一下计算机学院所有读者的名单 | D5: SELECT name FROM readers WHERE department = '计算机学院' | E5: 14 | F5: name 王晓明 李思雨 郭思雨 周子涵 刘宇轩 … | G5: 正确
A6: L1-005 | B6: L1 简单 Simple | C6: 现在馆里还有哪些书能借？把书名和还剩几本都列出来 | D6: SELECT title, available_copies FROM books WHERE available_copies > 0 | E6: 107 | F6: title | available_copies 数据库系统概念 | 4 深入理解计算机系统 | 2 人工智能：现代方法 | 8 机器学习 | 6 深度学习入门 | 8 … | G6: 正确
A7: L1-006 | B7: L1 简单 Simple | C7: 列出所有位于三楼的馆藏地名称 | D7: SELECT location_name FROM locations WHERE floor = 3 | E7: 1 | F7: location_name 三楼理科借阅区 | G7: 正确
A8: L1-007 | B8: L1 简单 Simple | C8: 查询2018年以前出版的图书书名和出版年份 | D8: SELECT title, publish_year FROM books WHERE publish_year < 2018 | E8: 30 | F8: title | publish_year 机器学习 | 2016 活着 | 2017 百年孤独 | 2017 平凡的世界 | 2017 许三观卖血记（第5版） | 2015 … | G8: 正确
A9: L1-008 | B9: L1 简单 Simple | C9: 查找所有未归还的借阅记录编号和应还日期 | D9: SELECT record_id, due_date FROM borrow_records WHERE return_date IS NULL | E9: 152 | F9: record_id | due_date 3 | 2025-06-27 4 | 2025-02-15 7 | 2025-01-07 11 | 2025-07-04 15 | 2024-07-18 … | G9: 正确
A10: L1-009 | B10: L1 简单 Simple | C10: 列出所有出版社的名称和所在地址 | D10: SELECT publisher_name, address FROM publishers | E10: 6 | F10: publisher_name | address 机械工业出版社 | 北京 清华大学出版社 | 北京 人民文学出版社 | 北京 高等教育出版社 | 北京 电子工业出版社 | 北京 … | G10: 正确
A11: L1-010 | B11: L1 简单 Simple | C11: 查询2023年9月1日以后注册的读者姓名和注册日期 | D11: SELECT name, register_date FROM readers WHERE register_date > '2023-09-01' | E11: 19 | F11: name | register_date 陈静 | 2024-09-01 郭俊杰 | 2024-09-01 黄博文 | 2024-09-01 郑磊 | 2024-09-01 马磊 | 2024-09-01 … | G11: 正确
A12: L1-011 | B12: L1 简单 Simple | C12: 哪些书现在已经被借空了？我想知道书名 | D12: SELECT title FROM books WHERE available_copies = 0 | E12: 13 | F12: title SQL必知必会 高等数学 月亮与六便士 概率论与数理统计 分布式系统原理 … | G12: 正确
A13: L1-012 | B13: L1 简单 Simple | C13: 查询所有研究生读者的姓名和学号 | D13: SELECT name, student_id FROM readers WHERE reader_type = '研究生' | E13: 20 | F13: name | student_id 陈静 | 2024220101 陈欣怡 | 202020043277 吴雨欣 | 202223212812 黄诗涵 | 202041163805 郭雪 | 202091478884 … | G13: 正确
... A24: L1-023 | B24: L1 简单 Simple | C24: 列出所有位于二楼的馆藏地名称 | D24: SELECT location_name FROM locations WHERE floor = 2 | E24: 1 | F24: location_name 二楼文学借阅区 | G24: 正确
A25: L1-024 | B25: L1 简单 Simple | C25: 有哪些书一次都没被借出去、复本全都在架上的？列个书名 | D25: SELECT title FROM books WHERE available_copies = total_copies | E25: 13 | F25: title 人工智能：现代方法 经济学原理 呐喊 白鹿原 计算机网络（第5版） … | G25: 有误 | H25: “一次都没被借出去”是历史口径，需要确认该图书在 borrow_records 中没有任何记录；available_copies = total_copies 只表示当前全部复本在架，借过又还清的书也满足，会多列。 | I25: SELECT title FROM books WHERE book_id NOT IN (SELECT DISTINCT book_id FROM borrow_records);
A26: L1-025 | B26: L1 简单 Simple | C26: 查询所有教师读者的姓名和职工号 | D26: SELECT name, student_id FROM readers WHERE reader_type = '教师' | E26: 10 | F26: name | student_id 赵敏 | T2019005 林雪 | T2021122 罗欣怡 | T2021133 马磊然 | T2022193 赵若曦 | T2019905 … | G26: 正确
A27: L1-026 | B27: L1 简单 Simple | C27: 列出2019年出版的图书书名和作者 | D27: SELECT title, author FROM books WHERE publish_year = 2019 | E27: 12 | F27: title | author 红楼梦 | 曹雪芹 围城 | 赵伟 市场营销学（第2版） | 林天佑 平凡的世界 | 罗博文 白鹿原（第3版） | 刘嘉怡 … | G27: 正确
A28: L1-027 | B28: L1 简单 Simple | C28: 查找没有续借过的借阅记录编号 | D28: SELECT record_id FROM borrow_records WHERE renew_count = 0 | E28: 593 | F28: record_id 2 4 5 6 7 … | G28: 正确
A29: L1-028 | B29: L1 简单 Simple | C29: 查询数学学院的所有读者姓名 | D29: SELECT name FROM readers WHERE department = '数学学院' | E29: 15 | F29: name 周晓明 吴嘉怡 马磊 陈静轩 朱敏 … | G29: 正确
A30: L1-029 | B30: L1 简单 Simple | C30: 列出所有出版社的名称 | D30: SELECT publisher_name FROM publishers | E30: 6 | F30: publisher_name 机械工业出版社 清华大学出版社 人民文学出版社 高等教育出版社 电子工业出版社 … | G30: 正确
A31: L1-030 | B31: L1 简单 Simple | C31: 查找应还日期在2025年6月之后的未归还借阅记录编号 | D31: SELECT record_id FROM borrow_records WHERE return_date IS NULL AND due_date > '2025-06-01' | E31: 67 | F31: record_id 3 11 20 21 40 … | G31: 问题有歧义 | H31: “2025年6月之后”可有两种理解：(a) 进入6月以后、含6月（现 SQL：due_date > '2025-06-01'）；(b) 6月结束以后、即7月1日起（due_date >= '2025-07-01'）。SQL 只对应 (a)，建议明确口径。 | I31: SELECT record_id FROM borrow_records WHERE return_date IS NULL AND due_date >= '2025-07-01'; -- 若按理解(b)
A32: L1-031 | B32: L1 简单 Simple | C32: 查询总复本数超过20册的图书书名和复本数 | D32: SELECT title, total_copies FROM books WHERE total_copies > 20 | E32: 24 | F32: title | total_copies 白鹿原 | 23 了不起的盖茨比 | 22 动物农场 | 21 英语语法大全 | 25 数据结构与算法分析（第2版） | 24 … | G32: 正确
A33: L1-032 | B33: L1 简单 Simple | C33: 我想找余华的书，馆里都有什么？ | D33: SELECT title FROM books WHERE author = '余华' | E33: 1 | F33: title 活着 | G33: 正确
A34: L1-033 | B34: L1 简单 Simple | C34: 列出计算机科学下的所有二级分类名称 | D34: SELECT category_name FROM categories WHERE parent_category = 1 | E34: 2 | F34: category_name 数据库技术 人工智能 | G34: 正确
A35: L1-034 | B35: L1 简单 Simple | C35: 查询2024年注册的读者姓名和注册日期 | D35: SELECT name, register_date FROM readers WHERE register_date LIKE '2024%' | E35: 19 | F35: name | register_date 陈静 | 2024-09-01 郭俊杰 | 2024-09-01 黄博文 | 2024-09-01 郑磊 | 2024-09-01 马磊 | 2024-09-01 … | G35: 正确
A36: L1-035 | B36: L1 简单 Simple | C36: 查找位于四楼的馆藏地名称 | D36: SELECT location_name FROM locations WHERE floor = 4 | E36: 1 | F36: location_name 四楼社科借阅区 | G36: 正确
A37: L1-036 | B37: L1 简单 Simple | C37: 哪些书快被借完了、可借的不到3本？书名和剩余数量都给我 | D37: SELECT title, available_copies FROM books WHERE available_copies < 3 | E37: 34 | F37: title | available_copies 深入理解计算机系统 | 2 SQL必知必会 | 0 红楼梦 | 1 Python编程实践 | 1 高等数学 | 0 … | G37: 正确
A38: L1-037 | B38: L1 简单 Simple | C38: 查询所有本科生读者的姓名和学号 | D38: SELECT name, student_id FROM readers WHERE reader_type = '本科生' | E38: 70 | F38: name | student_id 王晓明 | 2023011201 李思雨 | 2022030405 张伟 | 2021150607 周晓明 | 202188777447 郭洋 | 202256321751 … | G38: 正确
A39: L1-038 | B39: L1 简单 Simple | C39: 查找2015年出版的图书书名 | D39: SELECT title FROM books WHERE publish_year = 2015 | E39: 8 | F39: title 许三观卖血记（第5版） 分布式系统原理 西方经济学 动物农场 平凡的世界 … | G39: 正确
A40: L1-039 | B40: L1 简单 Simple | C40: 列出续借次数达到2次的借阅记录编号 | D40: SELECT record_id FROM borrow_records WHERE renew_count = 2 | E40: 44 | F40: record_id 1 8 30 39 43 … | G40: 正确
A41: L1-040 | B41: L1 简单 Simple | C41: 查询管理学院的所有读者姓名 | D41: SELECT name FROM readers WHERE department = '管理学院' | E41: 20 | F41: name 高嘉怡 胡静 徐嘉怡 郭嘉怡 吴雨欣 … | G41: 正确
A42: L1-041 | B42: L1 简单 Simple | C42: 查找作者是曹雪芹的图书书名 | D42: SELECT title FROM books WHERE author = '曹雪芹' | E42: 1 | F42: title 红楼梦 | G42: 正确
A43: L1-042 | B43: L1 简单 Simple | C43: 列出所有外文借阅区的架位范围 | D43: SELECT shelf_range FROM locations WHERE location_name LIKE '%外文%' | E43: 1 | F43: shelf_range J001-K040 | G43: 正确
A44: L1-043 | B44: L1 简单 Simple | C44: 查询2025年5月之后的借阅记录编号和借阅日期 | D44: SELECT record_id, borrow_date FROM borrow_records WHERE borrow_date > '2025-05-01' | E44: 110 | F44: record_id | borrow_date 3 | 2025-05-28 11 | 2025-06-04 12 | 2025-05-12 20 | 2025-06-12 21 | 2025-06-09 … | G44: 问题有歧义 | H44: “2025年5月之后”可理解为 (a) 含5月（现 SQL：borrow_date > '2025-05-01'）或 (b) 5月之后、即6月1日起（borrow_date >= '2025-06-01'）。SQL 只对应 (a)。 | I44: SELECT record_id, borrow_date FROM borrow_records WHERE borrow_date >= '2025-06-01'; -- 若按理解(b)
A45: L1-044 | B45: L1 简单 Simple | C45: 书名里带SQL的书有哪些？ | D45: SELECT title FROM books WHERE title LIKE '%SQL%' | E45: 1 | F45: title SQL必知必会 | G45: 正确
A46: L1-045 | B46: L1 简单 Simple | C46: 查询2021年注册的读者姓名 | D46: SELECT name FROM readers WHERE register_date LIKE '2021%' | E46: 18 | F46: name 张伟 周晓明 高嘉怡 徐嘉怡 刘宇轩 … | G46: 正确
A47: L1-046 | B47: L1 简单 Simple | C47: 列出总复本数在10到15之间的图书书名 | D47: SELECT title FROM books WHERE total_copies BETWEEN 10 AND 15 | E47: 30 | F47: title 深入理解计算机系统 深度学习入门 经济学原理 高等数学 围城 … | G47: 正确
A48: L1-047 | B48: L1 简单 Simple | C48: 查找归还日期在2025年3月的借阅记录编号 | D48: SELECT record_id FROM borrow_records WHERE return_date LIKE '2025-03%' | E48: 34 | F48: record_id 41 124 134 148 152 … | G48: 正确
A49: L1-048 | B49: L1 简单 Simple | C49: 查询经济学院的教师读者姓名 | D49: SELECT name FROM readers WHERE department = '经济学院' AND reader_type = '教师' | E49: 2 | F49: name 赵若曦 朱思雨 | G49: 正确
A50: L1-049 | B50: L1 简单 Simple | C50: 列出2023年出版的图书书名和作者 | D50: SELECT title, author FROM books WHERE publish_year = 2023 | E50: 10 | F50: title | author 管理学原理 | Robbins 白鹿原 | 郑伟 了不起的盖茨比 | 陈磊 离散数学（第5版） | 高洋 了不起的盖茨比 | 王静 … | G50: 正确
...

Sheet 汇总 Summary
A1: 复核结果汇总（自动计算）
A3: 判定 | B3: 合计 | C3: L1 | D3: L2 | E3: L3 | F3: L4
A4: 正确 | B4: =COUNTIF('复核 Review'!$G$2:$G$201,"正确") -> 193 | C4: =SUMPRODUCT((LEFT('复核 Review'!$A$2:$A$201,2)="L1")*('复核 Review'!$G$2:$G$201="正确")) -> 47 | D4: =SUMPRODUCT((LEFT('复核 Review'!$A$2:$A$201,2)="L2")*('复核 Review'!$G$2:$G$201="正确")) -> 50 | E4: =SUMPRODUCT((LEFT('复核 Review'!$A$2:$A$201,2)="L3")*('复核 Review'!$G$2:$G$201="正确")) -> 50 | F4: =SUMPRODUCT((LEFT('复核 Review'!$A$2:$A$201,2)="L4")*('复核 Review'!$G$2:$G$201="正确")) -> 46
A5: 有误 | B5: =COUNTIF('复核 Review'!$G$2:$G$201,"有误") -> 5 | C5: =SUMPRODUCT((LEFT('复核 Review'!$A$2:$A$201,2)="L1")*('复核 Review'!$G$2:$G$201="有误")) -> 1 | D5: =SUMPRODUCT((LEFT('复核 Review'!$A$2:$A$201,2)="L2")*('复核 Review'!$G$2:$G$201="有误")) -> 0 | E5: =SUMPRODUCT((LEFT('复核 Review'!$A$2:$A$201,2)="L3")*('复核 Review'!$G$2:$G$201="有误")) -> 0 | F5: =SUMPRODUCT((LEFT('复核 Review'!$A$2:$A$201,2)="L4")*('复核 Review'!$G$2:$G$201="有误")) -> 4
A6: 问题有歧义 | B6: =COUNTIF('复核 Review'!$G$2:$G$201,"问题有歧义") -> 2 | C6: =SUMPRODUCT((LEFT('复核 Review'!$A$2:$A$201,2)="L1")*('复核 Review'!$G$2:$G$201="问题有歧义")) -> 2 | D6: =SUMPRODUCT((LEFT('复核 Review'!$A$2:$A$201,2)="L2")*('复核 Review'!$G$2:$G$201="问题有歧义")) -> 0 | E6: =SUMPRODUCT((LEFT('复核 Review'!$A$2:$A$201,2)="L3")*('复核 Review'!$G$2:$G$201="问题有歧义")) -> 0 | F6: =SUMPRODUCT((LEFT('复核 Review'!$A$2:$A$201,2)="L4")*('复核 Review'!$G$2:$G$201="问题有歧义")) -> 0
A7: 未填 | B7: =COUNTBLANK('复核 Review'!$G$2:$G$201) -> 0 | C7: =SUMPRODUCT((LEFT('复核 Review'!$A$2:$A$201,2)="L1")*('复核 Review'!$G$2:$G$201="")) -> 0 | D7: =SUMPRODUCT((LEFT('复核 Review'!$A$2:$A$201,2)="L2")*('复核 Review'!$G$2:$G$201="")) -> 0 | E7: =SUMPRODUCT((LEFT('复核 Review'!$A$2:$A$201,2)="L3")*('复核 Review'!$G$2:$G$201="")) -> 0 | F7: =SUMPRODUCT((LEFT('复核 Review'!$A$2:$A$201,2)="L4")*('复核 Review'!$G$2:$G$201="")) -> 0
A8: 合计 | B8: =SUM(B4:B7) -> 200 | C8: =SUM(C4:C7) -> 50 | D8: =SUM(D4:D7) -> 50 | E8: =SUM(E4:E7) -> 50 | F8: =SUM(F4:F7) -> 50

Sheet 分歧处理 Resolution
A1: 编号 ID | B1: 复核人意见 Reviewer view | C1: 作者意见 Author view | D1: 讨论后结论 Resolution | E1: Gold SQL 是否修改 Changed? (是/否) | F1: 修改后的 Gold SQL New gold SQL | G1: 日期 Date
A2: L1-024 | B2: available_copies = total_copies 只代表当前全部复本在架，借过又还清的书也满足，不能保证“一次都没被借出去”；应按 borrow_records 历史判断。 | C2: 核对后认可原写法不完整。题目有两个条件：“一次都没被借出去”与“复本全都在架上”。复核人建议的写法只保留了前一个条件；而库中 8 本从未被借过的书里有 7 本复本并不全在架，只用前一个条件会多列这 7 本。因此两个条件都应保留。 | D2: 采纳复核人“需按借阅历史判断”的意见，同时保留题目中“复本全都在架”的条件：Gold SQL 改为两个条件同时满足。 | E2: 是 | F2: SELECT title FROM books WHERE available_copies = total_copies AND book_id NOT IN (SELECT DISTINCT book_id FROM borrow_records); | G2: 46299
A3: L1-030 | B3: “2025年6月之后”有两种理解：含6月（现写法 due_date > '2025-06-01'）或7月1日起；SQL 只对应前者。 | C3: 本研究中“X月之后”统一按“晚于X月1日”处理（即 > '2025-06-01'，不含1日当天），与现 SQL 一致；模型未被告知这一口径，论文中将该题列为有歧义并说明所采用的读法。 | D3: 维持原 SQL；论文 3.4.1 节写明 gold 采用“晚于X月1日”的读法，并说明模型可能按另一种读法作答。 | E3: 否 | F3: （维持原 Gold SQL，未修改） | G3: 46299
A4: L1-043 | B4: “2025年5月之后”可理解为含5月（现写法）或6月1日起；SQL 只对应前者。 | C4: 本研究中“X月之后”统一按“晚于X月1日”处理（即 > '2025-05-01'，不含1日当天），与现 SQL 一致；模型未被告知这一口径，论文中将该题列为有歧义并说明所采用的读法。 | D4: 维持原 SQL；论文 3.4.1 节写明 gold 采用“晚于X月1日”的读法，并说明模型可能按另一种读法作答。 | E4: 否 | F4: （维持原 Gold SQL，未修改） | G4: 46299
A5: L4-024 | B5: “至少2次不同图书”要求至少2本不同的书被续借过，每本 renew_count >= 1 即可；现写法要求每本 renew_count >= 2，会漏掉“两本书各续一次”的读者。 | C5: 认可：阈值应落在“不同图书的数量”上，续借判定用 renew_count >= 1。 | D5: 采纳复核人意见，改为 renew_count >= 1 且 HAVING COUNT(DISTINCT book_id) >= 2。 | E5: 是 | F5: SELECT r.name FROM readers r JOIN borrow_records br ON r.reader_id = br.reader_id WHERE br.renew_count >= 1 GROUP BY r.reader_id, r.name HAVING COUNT(DISTINCT br.book_id) >= 2; | G5: 46299
A6: L4-025 | B6: “在馆可借”按约定是 available_copies > 0；现写法用 available_copies = total_copies（全部在馆），条件过严。 | C6: 认可：题目只要求有复本可借，不应要求全部复本在馆。 | D6: 采纳复核人意见，把 available_copies = total_copies 改为 available_copies > 0。 | E6: 是 | F6: SELECT b.title, l.location_name FROM books b JOIN categories c ON b.category_id = c.category_id JOIN locations l ON c.location_id = l.location_id WHERE b.available_copies > 0 AND b.book_id NOT IN (SELECT DISTINCT book_id FROM borrow_records); | G6: 46299
A7: L4-031 | B7: 初判“全馆图书平均借阅量”应含从未被借的书（记0），现 AVG 只对有记录的书计算，阈值偏高。 | C7: 该分析用于在“发生过借阅的图书”中找相对低借阅的书目，基线取流通图书均值；零借阅图书已通过 LEFT JOIN + COALESCE 纳入结果，若改用全馆均值会改变该指标的既定口径。 | D7: 经讨论，复核人接受作者对该指标口径的说明（基线为流通图书均值，零借阅书仍在结果中），撤回初判，维持原 SQL。 | E7: 否 | F7: （维持原 Gold SQL，未修改） | G7: 46299
A8: L4-046 | B8: “所有读者的平均未归还数量”分母应为全部读者（含0本读者）；现 CTE 只保留有未还记录者，结果约1.88偏高，应为 152/100 = 1.52。 | C8: 核对数据认可：未归还共152册、读者共100人，人均应含0本读者，原写法分母取小了。 | D8: 采纳复核人意见，改为对 readers 做 LEFT JOIN 统计后再取平均。 | E8: 是 | F8: WITH ru AS (SELECT r.reader_id, COUNT(br.record_id) AS cnt FROM readers r LEFT JOIN borrow_records br ON r.reader_id = br.reader_id AND br.return_date IS NULL GROUP BY r.reader_id) SELECT AVG(cnt) AS avg_unreturned FROM ru; | G8: 46299

Sheet 数据库结构 Schema
A1: 数据库结构（SQLite，模拟数据，无真实读者信息）
A3: -- 高校图书馆核心业务数据库（SQLite）。日期字段为 'YYYY-MM-DD' 文本；未归还时 return_date 为 NULL。
A4: CREATE TABLE books (book_id INTEGER PRIMARY KEY, isbn TEXT, title TEXT, author TEXT, publisher_id INTEGER, category_id INTEGER, publish_year INTEGER, total_copies INTEGER, available_copies INTEGER);
A5: CREATE TABLE readers (reader_id INTEGER PRIMARY KEY, name TEXT, student_id TEXT, department TEXT, reader_type TEXT /*本科生/研究生/教师*/, register_date TEXT);
A6: CREATE TABLE borrow_records (record_id INTEGER PRIMARY KEY, reader_id INTEGER, book_id INTEGER, borrow_date TEXT, due_date TEXT, return_date TEXT, renew_count INTEGER);
A7: CREATE TABLE categories (category_id INTEGER PRIMARY KEY, category_name TEXT, parent_category INTEGER, location_id INTEGER);
A8: CREATE TABLE publishers (publisher_id INTEGER PRIMARY KEY, publisher_name TEXT, address TEXT);
A9: CREATE TABLE locations (location_id INTEGER PRIMARY KEY, location_name TEXT, floor INTEGER, shelf_range TEXT);
A11: 术语约定（系统预处理层使用，复核时可参考）
A12: 在馆 → books.available_copies > 0
A13: 可借 → books.available_copies > 0
A14: 在架 → books.available_copies > 0
... A26: 现刊 → 本库未建期刊表，提示用户该查询超出范围

Sheet 复核人信息 Reviewer
A1: 姓名 Name | B1: 吴涛
A2: 职称/职务 Title / position | B2: 图书馆信息科科长
A3: 单位 Institution | B3: 郑州工商学院图书馆
A4: 与 SQL/数据库相关的经历 Relevant experience | B4: 从事图书馆信息化工作多年，负责本馆集成管理系统（编目、流通、读者等模块）的日常运维、数据管理与统计报表；熟练使用 SQL 对馆藏、读者、借阅记录进行查询与核对，能编写多表 JOIN、GROUP BY/HAVING 聚合及嵌套子查询。
A5: 复核开始日期 Start date | B5: 2026-10-04
A6: 复核完成日期 Completion date | B6: 2026-10-04
A7: 签名 Signature | B7: 吴涛
